<?xml version="1.0" ?>
<!-- =================================================================================== -->
<!-- |    This document was autogenerated by xacro from /home/joe/Desktop/mrover_catkin_ws/src/mrover/rover_description/arm/arm.xacro | -->
<!-- |    EDITING THIS FILE BY HAND IS NOT RECOMMENDED                                 | -->
<!-- =================================================================================== -->
<robot name="mrover_arm">
    <virtual_joint child_link="chassis-a" name="" parent_frame="world" type="fixed" />
    <link name="base_link">
        <inertial>
            <mass value="3.0" />
            <inertia ixx="102.5" ixy="0.0" ixz="0.0" iyy="24.5" iyz="0.0" izz="102.5" />
            <origin xyz="0 0 0" rpy="0 0 0" />
        </inertial>
        <visual>
            <origin rpy="0 0 0" xyz="0 0 -9.5" />
            <geometry>
                <mesh filename="package://mrover/rover_description/arm/rover.stl" />
            </geometry>
            <material name="red">
                <color rgba="1 1 1 1" />
            </material>
        </visual>
        <collision>
            <origin rpy="0 0 0" xyz="0 0 -9.5" />
            <geometry>
                <mesh filename="package://mrover/rover_description/arm/rover.stl" />
            </geometry>
        </collision>
    </link>
    <link name="chassisToa">
        <visual>
            <origin rpy="0 0 0" xyz="0 0 0" />
            <geometry>
                <mesh filename="package://mrover/rover_description/arm/chassis-a.stl" />
            </geometry>
            <material name="red">
                <color rgba="1 0 0 1" />
            </material>
        </visual>
        <collision>
            <origin rpy="0 0 0" xyz="0.0 0.0 -2.5" />
            <geometry>
                <cylinder length="2.5" radius="3.75" />
            </geometry>
        </collision>
        <collision>
            <origin rpy="0 0 0" xyz="3.6467207 3.6590503 -1.7206994" />
            <geometry>
                <cylinder length="1.9413988" radius="1.75" />
            </geometry>
        </collision>
        <inertial>
            <origin rpy="0 0 0" xyz="0 0 -2.5" />
            <!-- mass in kg -->
            <mass value="0.5" />
            <inertia ixx="2.3" ixy="0" ixz="0" iyy="2.3" iyz="0" izz="3.5" />
        </inertial>
    </link>
    <link name="aTob">
        <visual>
            <origin rpy="0 0 0" xyz="0 0 0" />
            <geometry>
                <mesh filename="package://mrover/rover_description/arm/a-b.stl" />
            </geometry>
            <material name="orange">
                <color rgba="1 0.43 0 1" />
            </material>
        </visual>
        <collision>
            <origin rpy="0 0 0" xyz="0 -1.75 3" />
            <geometry>
                <box size="2 3 6" />
            </geometry>
        </collision>
        <collision>
            <origin rpy="0 0 0" xyz="0.0 0.0 0.25" />
            <geometry>
                <cylinder length="1.0" radius="2" />
            </geometry>
        </collision>
        <inertial>
            <origin rpy="0 0 0" xyz="0 -1.75 3" />
            <!-- mass in kg -->
            <mass value="0.5" />
            <inertia ixx="1.9" ixy="0" ixz="0" iyy="0.7" iyz="0" izz="0.5" />
        </inertial>
    </link>
    <link name="bToc">
        <visual>
            <origin rpy="0 0 0" xyz="0 0 0" />
            <geometry>
                <mesh filename="package://mrover/rover_description/arm/b-c.stl" />
            </geometry>
            <material name="yellow">
                <color rgba="1 1 0 1" />
            </material>
        </visual>
        <collision>
            <origin rpy="0.48 0 0" xyz="0 9 5" />
            <geometry>
                <box size="2 20 2" />
            </geometry>
        </collision>
        <collision>
            <origin rpy="0 1.570796 0" xyz="1.25 20.25 10.75" />
            <geometry>
                <cylinder length="6.5" radius="2" />
            </geometry>
        </collision>
        <collision>
            <origin rpy="1.8707960000000001 0 0" xyz="0.0 7.5 8.5" />
            <geometry>
                <cylinder length="19.0" radius="1" />
            </geometry>
        </collision>
        <inertial>
            <origin rpy="0 0 0" xyz="0 12 0" />
            <!-- mass in kg -->
            <mass value="0.5" />
            <inertia ixx="24" ixy="0" ixz="0" iyy="0.75" iyz="0" izz="24" />
        </inertial>
    </link>
    <link name="cTod">
        <visual>
            <origin rpy="0 0 0" xyz="0 0 0" />
            <geometry>
                <mesh filename="package://mrover/rover_description/arm/c-d.stl" />
            </geometry>
            <material name="green">
                <color rgba="0.43 1 0 1" />
            </material>
        </visual>
        <collision>
            <origin rpy="-0.17 0 0" xyz="-4.5 0.0 0.25" />
            <geometry>
                <cylinder length="5.5" radius="3.75" />
            </geometry>
        </collision>
        <inertial>
            <origin rpy="0 0 0" xyz="-1 0 0" />
            <!-- mass in kg -->
            <mass value="0.5" />
            <inertia ixx="3.2" ixy="0" ixz="0" iyy="3.2" iyz="0" izz="16" />
        </inertial>
    </link>
    <link name="dToe">
        <visual>
            <origin rpy="0 0 0" xyz="0 0 0" />
            <geometry>
                <mesh filename="package://mrover/rover_description/arm/d-e.stl" />
            </geometry>
            <material name="blue">
                <color rgba="0 0 1 1" />
            </material>
        </visual>
        <collision>
            <origin rpy="-1.520796 0 0" xyz="0 0 -7" />
            <geometry>
                <box size="4 20 4" />
            </geometry>
        </collision>
        <collision>
            <origin rpy="0 1.570796 0" xyz="0.0 0.0 -17.0" />
            <geometry>
                <cylinder length="6.0" radius="2.5" />
            </geometry>
        </collision>
        <inertial>
            <origin rpy="-0.558505 0 0" xyz="0 -7.6324 4.7693" />
            <!-- mass in kg -->
            <mass value="0.5" />
            <inertia ixx="17" ixy="0" ixz="0" iyy="0.5" iyz="0" izz="17" />
        </inertial>
    </link>
    <link name="eTof">
        <visual>
            <origin rpy="0 0 0" xyz="0 0 0" />
            <geometry>
                <mesh filename="package://mrover/rover_description/arm/e-f.stl" />
            </geometry>
            <material name="violet">
                <color rgba="0.5 0 1 1" />
            </material>
        </visual>
        <collision>
            <origin rpy="0 1.570796 0" xyz="-1.75 1.8 0.0" />
            <geometry>
                <cylinder length="9.5" radius="3" />
            </geometry>
        </collision>
        <inertial>
            <origin rpy="0 0 0" xyz="0 0 -3" />
            <!-- mass in kg -->
            <mass value="0.5" />
            <inertia ixx="1.6" ixy="0" ixz="0" iyy="1.6" iyz="0" izz="0.25" />
        </inertial>
    </link>
    <link name="hand">
        <visual>
            <origin rpy="0 0 0" xyz="0 0 0" />
            <geometry>
                <mesh filename="package://mrover/rover_description/arm/hand.stl" />
            </geometry>
            <material name="pink">
                <color rgba="1 0 1 1" />
            </material>
        </visual>
        <collision>
            <origin rpy="1.570796 0 0" xyz="-2.25 1 0.5" />
            <geometry>
                <box size="8 3.5 8.5" />
            </geometry>
        </collision>
        <collision>
            <origin rpy="1.570796 0 0" xyz="-1 3.5 8.75" />
            <geometry>
                <box size="3.5 3.5 5" />
            </geometry>
        </collision>
        <collision>
            <origin rpy="0 0 0" xyz="0.0 2.3 4.5" />
            <geometry>
                <cylinder length="9.0" radius="0.75" />
            </geometry>
        </collision>
        <collision>
            <origin rpy="0 0 0" xyz="-1.6 -1.5 -2" />
            <geometry>
                <box size="1 2.5 2.5" />
            </geometry>
        </collision>
        <inertial>
            <origin rpy="0 0 0" xyz="0 0 -2.5" />
            <!-- mass in kg -->
            <mass value="0.5" />
            <inertia ixx="2.2" ixy="0" ixz="0" iyy="4" iyz="0" izz="2.2" />
        </inertial>
    </link>
    <link name="world" />
    <joint name="virtual_joint" type="fixed">
        <parent link="world" />
        <child link="base_link" />
        <origin rpy="0 0 0" xyz="0 0 9.5" />
    </joint>
    <joint name="base_link_connection" type="fixed">
        <origin rpy="0 0 0" xyz="0 15.55 11" />
        <parent link="base_link" />
        <child link="chassisToa" />
        <axis xyz="0 0 0" />
        <!-- effort in N-m, velocity in rad/s -->
        <limit effort="30" lower="0" upper="0" velocity="1" />
        <!-- damping in N-m-s/rad -->
        <dynamics damping="1.0" />
    </joint>
    <joint name="joint_a" type="continuous">
        <origin rpy="0 0 0" xyz="0 0 0" />
        <parent link="chassisToa" />
        <child link="aTob" />
        <axis xyz="0 0 1" />
        <!-- effort in N-m, velocity in rad/s -->
        <limit effort="30" lower="-3.14" upper="3.14" velocity="1" />
        <!-- damping in N-m-s/rad -->
        <dynamics damping="1.0" />
    </joint>
    <joint name="joint_b" type="revolute">
        <origin rpy="0.593412 0 0" xyz="0 1.33 0.99" />
        <parent link="aTob" />
        <child link="bToc" />
        <axis xyz="1 0 0" />
        <!-- effort in N-m, velocity in rad/s -->
        <limit effort="30" lower="-1.064651" upper="0" velocity="1" />
        <!-- damping in N-m-s/rad -->
        <dynamics damping="1.0" />
    </joint>
    <joint name="joint_c" type="revolute">
        <origin rpy="-0.436332 0 0" xyz="0 20.11 10.75" />
        <parent link="bToc" />
        <child link="cTod" />
        <axis xyz="1 0 0" />
        <!-- effort in N-m, velocity in rad/s -->
        <limit effort="30" lower="-0.087267" upper="4.886922" velocity="1" />
        <!-- damping in N-m-s/rad -->
        <dynamics damping="1.0" />
    </joint>
    <joint name="joint_d" type="revolute">
        <origin rpy="-0.15708 -0.0174533 0" xyz="-4.4 -0.42 -2.535" />
        <parent link="cTod" />
        <child link="dToe" />
        <axis xyz="0 0 1" />
        <!-- effort in N-m, velocity in rad/s -->
        <limit effort="30" lower="-3.14" upper="3.14" velocity="1" />
        <!-- damping in N-m-s/rad -->
        <dynamics damping="1.0" />
    </joint>
    <joint name="joint_e" type="revolute">
        <origin rpy="0 0 -1.649336" xyz="2.55 0.2 -17" />
        <parent link="dToe" />
        <child link="eTof" />
        <axis xyz="0 1 0" />
        <!-- effort in N-m, velocity in rad/s -->
        <limit effort="30" lower="-3.59538" upper="0.610865" velocity="1" />
        <!-- damping in N-m-s/rad -->
        <dynamics damping="1.0" />
    </joint>
    <joint name="joint_f" type="revolute">
        <origin rpy="0 0 0" xyz="-6.3 1.75 0" />
        <parent link="eTof" />
        <child link="hand" />
        <axis xyz="1 0 0" />
        <!-- effort in N-m, velocity in rad/s -->
        <limit effort="30" lower="-0.523599" upper="6.28" velocity="1" />
        <!-- damping in N-m-s/rad -->
        <dynamics damping="1.0" />
    </joint>
    <transmission name="trans_joint_a">
        <type>transmission_interface/SimpleTransmission</type>
        <joint name="joint_a">
            <hardwareInterface>hardware_interface/PositionJointInterface</hardwareInterface>
        </joint>
        <actuator name="joint_a_motor">
            <hardwareInterface>hardware_interface/PositionJointInterface</hardwareInterface>
            <mechanicalReduction>1</mechanicalReduction>
        </actuator>
    </transmission>
    <transmission name="trans_joint_b">
        <type>transmission_interface/SimpleTransmission</type>
        <joint name="joint_b">
            <hardwareInterface>hardware_interface/PositionJointInterface</hardwareInterface>
        </joint>
        <actuator name="joint_b_motor">
            <hardwareInterface>hardware_interface/PositionJointInterface</hardwareInterface>
            <mechanicalReduction>1</mechanicalReduction>
        </actuator>
    </transmission>
    <transmission name="trans_joint_c">
        <type>transmission_interface/SimpleTransmission</type>
        <joint name="joint_c">
            <hardwareInterface>hardware_interface/PositionJointInterface</hardwareInterface>
        </joint>
        <actuator name="joint_c_motor">
            <hardwareInterface>hardware_interface/PositionJointInterface</hardwareInterface>
            <mechanicalReduction>1</mechanicalReduction>
        </actuator>
    </transmission>
    <transmission name="trans_joint_d">
        <type>transmission_interface/SimpleTransmission</type>
        <joint name="joint_d">
            <hardwareInterface>hardware_interface/PositionJointInterface</hardwareInterface>
        </joint>
        <actuator name="joint_d_motor">
            <hardwareInterface>hardware_interface/PositionJointInterface</hardwareInterface>
            <mechanicalReduction>1</mechanicalReduction>
        </actuator>
    </transmission>
    <transmission name="trans_joint_e">
        <type>transmission_interface/SimpleTransmission</type>
        <joint name="joint_e">
            <hardwareInterface>hardware_interface/PositionJointInterface</hardwareInterface>
        </joint>
        <actuator name="joint_e_motor">
            <hardwareInterface>hardware_interface/PositionJointInterface</hardwareInterface>
            <mechanicalReduction>1</mechanicalReduction>
        </actuator>
    </transmission>
    <transmission name="trans_joint_f">
        <type>transmission_interface/SimpleTransmission</type>
        <joint name="joint_f">
            <hardwareInterface>hardware_interface/PositionJointInterface</hardwareInterface>
        </joint>
        <actuator name="joint_f_motor">
            <hardwareInterface>hardware_interface/PositionJointInterface</hardwareInterface>
            <mechanicalReduction>1</mechanicalReduction>
        </actuator>
    </transmission>
    <gazebo reference="chassisToa">
        <material>Gazebo/White</material>
        <mu1>0.2</mu1>
        <mu2>0.2</mu2>
        <selfCollide>false</selfCollide>
        <plugin name="gazebo_ros_control">
            <robotNamespace>/</robotNamespace>
        </plugin>
    </gazebo>
    <gazebo reference="aTob">
        <material>Gazebo/White</material>
        <mu1>0.2</mu1>
        <mu2>0.2</mu2>
        <selfCollide>false</selfCollide>
    </gazebo>
    <gazebo reference="bToc">
        <material>Gazebo/White</material>
        <mu1>0.2</mu1>
        <mu2>0.2</mu2>
        <selfCollide>false</selfCollide>
    </gazebo>
    <gazebo reference="cTod">
        <material>Gazebo/White</material>
        <mu1>0.2</mu1>
        <mu2>0.2</mu2>
        <selfCollide>false</selfCollide>
    </gazebo>
    <gazebo reference="dToe">
        <material>Gazebo/White</material>
        <mu1>0.2</mu1>
        <mu2>0.2</mu2>
        <selfCollide>false</selfCollide>
    </gazebo>
    <gazebo reference="eTof">
        <material>Gazebo/White</material>
        <mu1>0.2</mu1>
        <mu2>0.2</mu2>
        <selfCollide>false</selfCollide>
    </gazebo>
    <gazebo reference="hand">
        <material>Gazebo/White</material>
        <mu1>0.2</mu1>
        <mu2>0.2</mu2>
        <selfCollide>false</selfCollide>
    </gazebo>
    <gazebo>
        <plugin filename="libgazebo_ros_control.so" name="gazebo_ros_control" />
    </gazebo>
</robot>

