<?xml version="1.0" ?>
<!-- =================================================================================== -->
<!-- |    This document was autogenerated by xacro from /home/iyrn/catkin_ws/src/mrover/rover_description/arm/arm.xacro | -->
<!-- |    EDITING THIS FILE BY HAND IS NOT RECOMMENDED                                 | -->
<!-- =================================================================================== -->
<robot name="mrover_arm">
    <virtual_joint child_link="chassis-a" name="" parent_frame="world" type="fixed" />
    <link name="chassisToa">
        <visual>
            <origin rpy="0 0 0" xyz="0 0 0" />
            <geometry>
                <mesh filename="package://mrover/rover_description/arm/chassis-a.stl" />
            </geometry>
            <material name="red">
                <color rgba="1 0 0 1" />
            </material>
        </visual>
        <collision>
            <origin rpy="0 0 0" xyz="0.0 0.0 -2.5" />
            <geometry>
                <cylinder length="2.5" radius="3.75" />
            </geometry>
        </collision>
        <collision>
            <origin rpy="0 0 0" xyz="-3.6467207 3.6590503 -1.6913988" />
            <geometry>
                <cylinder length="2.0" radius="1.75" />
            </geometry>
        </collision>
        <inertial>
            <mass value="0.1" />
            <origin xyz="0 0 0" rpy="0 0 0" />
            <inertia ixx="0.03" iyy="0.03" izz="0.03" ixy="0.0" ixz="0.0" iyz="0.0" />
        </inertial>
    </link>
    <link name="aTob">
        <visual>
            <origin rpy="0 0 0" xyz="0 0 0" />
            <geometry>
                <mesh filename="package://mrover/rover_description/arm/a-b.stl" />
            </geometry>
            <material name="orange">
                <color rgba="1 0.43 0 1" />
            </material>
        </visual>
        <collision>
            <origin rpy="0 0 0" xyz="0 -1.75 3" />
            <geometry>
                <box size="2 3 6" />
            </geometry>
        </collision>
        <collision>
            <origin rpy="0 0 0" xyz="0.0 0.0 0.25" />
            <geometry>
                <cylinder length="1.0" radius="2" />
            </geometry>
        </collision>
        <inertial>
            <mass value="0.1" />
            <origin xyz="0 0 0" rpy="0 0 0" />
            <inertia ixx="0.03" iyy="0.03" izz="0.03" ixy="0.0" ixz="0.0" iyz="0.0" />
        </inertial>
    </link>
    <link name="bToc">
        <visual>
            <origin rpy="0 0 0" xyz="0 0 0" />
            <geometry>
                <mesh filename="package://mrover/rover_description/arm/b-c.stl" />
            </geometry>
            <material name="yellow">
                <color rgba="1 1 0 1" />
            </material>
        </visual>
        <collision>
            <origin rpy="0 0 0" xyz="0 12 0" />
            <geometry>
                <box size="3 24 3" />
            </geometry>
        </collision>
        <collision>
            <origin rpy="0 1.570796 0" xyz="2.5 23.0 0.0" />
            <geometry>
                <cylinder length="5.0" radius="1" />
            </geometry>
        </collision>
        <collision>
            <origin rpy="1.270796 0 0" xyz="0.0 8.5 3.75" />
            <geometry>
                <cylinder length="17.0" radius="1" />
            </geometry>
        </collision>
        <inertial>
            <mass value="0.1" />
            <origin xyz="0 0 0" rpy="0 0 0" />
            <inertia ixx="0.03" iyy="0.03" izz="0.03" ixy="0.0" ixz="0.0" iyz="0.0" />
        </inertial>
    </link>
    <link name="cTod">
        <visual>
            <origin rpy="0 0 0" xyz="0 0 0" />
            <geometry>
                <mesh filename="package://mrover/rover_description/arm/c-d-blender.stl" />
            </geometry>
            <material name="green">
                <color rgba="0.43 1 0 1" />
            </material>
        </visual>
        <collision>
            <origin rpy="0 1.570796 0" xyz="-1.0 0.0 0.0" />
            <geometry>
                <cylinder length="8.0" radius="2" />
            </geometry>
        </collision>
        <inertial>
            <mass value="0.1" />
            <origin xyz="0 0 0" rpy="0 0 0" />
            <inertia ixx="0.03" iyy="0.03" izz="0.03" ixy="0.0" ixz="0.0" iyz="0.0" />
        </inertial>
    </link>
    <link name="dToe">
        <visual>
            <origin rpy="0 0 0" xyz="0 0 0" />
            <geometry>
                <mesh filename="package://mrover/rover_description/arm/d-e-blender.stl" />
            </geometry>
            <material name="blue">
                <color rgba="0 0 1 1" />
            </material>
        </visual>
        <collision>
            <origin rpy="-0.558505 0 0" xyz="0 -7.6324 4.7693" />
            <geometry>
                <box size="2.5 20 2.5" />
            </geometry>
        </collision>
        <collision>
            <origin rpy="-0.558505 0 0" xyz="1 -13.75 9.5" />
            <geometry>
                <box size="3 3 6" />
            </geometry>
        </collision>
        <inertial>
            <mass value="0.1" />
            <origin xyz="0 0 0" rpy="0 0 0" />
            <inertia ixx="0.03" iyy="0.03" izz="0.03" ixy="0.0" ixz="0.0" iyz="0.0" />
        </inertial>
    </link>
    <link name="eTof">
        <visual>
            <origin rpy="1.67552 0 0" xyz="0 0 0" />
            <geometry>
                <mesh filename="package://mrover/rover_description/arm/e-f-blender.stl" />
            </geometry>
            <material name="violet">
                <color rgba="0.5 0 1 1" />
            </material>
        </visual>
        <collision>
            <origin rpy="0 0 0" xyz="-0.75 0.0 -3.0" />
            <geometry>
                <cylinder length="6.0" radius="1" />
            </geometry>
        </collision>
        <inertial>
            <mass value="0.1" />
            <origin xyz="0 0 0" rpy="0 0 0" />
            <inertia ixx="0.03" iyy="0.03" izz="0.03" ixy="0.0" ixz="0.0" iyz="0.0" />
        </inertial>
    </link>
    <link name="hand">
        <visual>
            <origin rpy="-1.67552 0 3.141592" xyz="0 0 0" />
            <geometry>
                <mesh filename="package://mrover/rover_description/arm/hand.stl" />
            </geometry>
            <material name="pink">
                <color rgba="1 0 1 1" />
            </material>
        </visual>
        <collision>
            <origin rpy="0 0 0" xyz="0 0 -2.5" />
            <geometry>
                <box size="7 2 7" />
            </geometry>
        </collision>
        <collision>
            <origin rpy="0 0 0" xyz="0 -8 0" />
            <geometry>
                <box size="3 2 4" />
            </geometry>
        </collision>
        <collision>
            <origin rpy="1.570796 0 0" xyz="-1.5 -4.5 -0.5" />
            <geometry>
                <cylinder length="9.0" radius="0.75" />
            </geometry>
        </collision>
        <inertial>
            <mass value="0.1" />
            <origin xyz="0 0 0" rpy="0 0 0" />
            <inertia ixx="0.03" iyy="0.03" izz="0.03" ixy="0.0" ixz="0.0" iyz="0.0" />
        </inertial>
    </link>
    <joint name="joint_a" type="continuous">
        <origin rpy="0 0 0" xyz="0 0 0" />
        <parent link="chassisToa" />
        <child link="aTob" />
        <axis xyz="0 0 1" />
        <!-- effort in N-m, velocity in rad/s -->
        <limit effort="30" lower="-3.14" upper="3.14" velocity="1" />
    </joint>
    <joint name="joint_b" type="revolute">
        <origin rpy="0 0 0" xyz="0 1.41293 1.13303" />
        <parent link="aTob" />
        <child link="bToc" />
        <axis xyz="1 0 0" />
        <!-- effort in N-m, velocity in rad/s -->
        <limit effort="30" lower="0.035" upper="1.09" velocity="1" />
    </joint>
    <joint name="joint_c" type="revolute">
        <origin rpy="0 0 0" xyz="-4.59961 22.83397 0.38119" />
        <parent link="bToc" />
        <child link="cTod" />
        <axis xyz="1 0 0" />
        <!-- effort in N-m, velocity in rad/s -->
        <limit effort="30" lower="-3.01" upper="2.73" velocity="1" />
    </joint>
    <joint name="joint_d" type="revolute">
        <origin rpy="0 0 0" xyz="0 -1.4699 0.963976" />
        <parent link="cTod" />
        <child link="dToe" />
        <axis xyz="0 0.84805 -0.52992" />
        <!-- effort in N-m, velocity in rad/s -->
        <limit effort="30" lower="-3.14" upper="3.14" velocity="1" />
    </joint>
    <joint name="joint_e" type="revolute">
        <origin rpy="0 0 0" xyz="-2.30884 -14.2085 9.01643" />
        <parent link="dToe" />
        <child link="eTof" />
        <axis xyz="1 0 0" />
        <!-- effort in N-m, velocity in rad/s -->
        <limit effort="30" lower="-2.68" upper="2.68" velocity="1" />
    </joint>
    <joint name="joint_f" type="revolute">
        <origin rpy="0 0 0" xyz="-0.817441 0.678501 -6.45623" />
        <parent link="eTof" />
        <child link="hand" />
        <axis xyz="0 0 1" />
        <!-- effort in N-m, velocity in rad/s -->
        <limit effort="30" lower="-3.14" upper="3.14" velocity="1" />
    </joint>
    <transmission name="trans_joint_a">
        <type>transmission_interface/SimpleTransmission</type>
        <joint name="joint_a">
            <hardwareInterface>hardware_interface/EffortJointInterface</hardwareInterface>
        </joint>
        <actuator name="joint_a_motor">
            <hardwareInterface>hardware_interface/EffortJointInterface</hardwareInterface>
            <mechanicalReduction>1</mechanicalReduction>
        </actuator>
    </transmission>
    <transmission name="trans_joint_b">
        <type>transmission_interface/SimpleTransmission</type>
        <joint name="joint_b">
            <hardwareInterface>hardware_interface/EffortJointInterface</hardwareInterface>
        </joint>
        <actuator name="joint_b_motor">
            <hardwareInterface>hardware_interface/EffortJointInterface</hardwareInterface>
            <mechanicalReduction>1</mechanicalReduction>
        </actuator>
    </transmission>
    <transmission name="trans_joint_c">
        <type>transmission_interface/SimpleTransmission</type>
        <joint name="joint_c">
            <hardwareInterface>hardware_interface/EffortJointInterface</hardwareInterface>
        </joint>
        <actuator name="joint_c_motor">
            <hardwareInterface>hardware_interface/EffortJointInterface</hardwareInterface>
            <mechanicalReduction>1</mechanicalReduction>
        </actuator>
    </transmission>
    <transmission name="trans_joint_d">
        <type>transmission_interface/SimpleTransmission</type>
        <joint name="joint_d">
            <hardwareInterface>hardware_interface/EffortJointInterface</hardwareInterface>
        </joint>
        <actuator name="joint_d_motor">
            <hardwareInterface>hardware_interface/EffortJointInterface</hardwareInterface>
            <mechanicalReduction>1</mechanicalReduction>
        </actuator>
    </transmission>
    <transmission name="trans_joint_e">
        <type>transmission_interface/SimpleTransmission</type>
        <joint name="joint_e">
            <hardwareInterface>hardware_interface/EffortJointInterface</hardwareInterface>
        </joint>
        <actuator name="joint_e_motor">
            <hardwareInterface>hardware_interface/EffortJointInterface</hardwareInterface>
            <mechanicalReduction>1</mechanicalReduction>
        </actuator>
    </transmission>
    <transmission name="trans_joint_f">
        <type>transmission_interface/SimpleTransmission</type>
        <joint name="joint_f">
            <hardwareInterface>hardware_interface/EffortJointInterface</hardwareInterface>
        </joint>
        <actuator name="joint_f_motor">
            <hardwareInterface>hardware_interface/EffortJointInterface</hardwareInterface>
            <mechanicalReduction>1</mechanicalReduction>
        </actuator>
    </transmission>
    <gazebo>
        <plugin name="gazebo_ros_control" filename="libgazebo_ros_control.so">
            <robotNamespace>/</robotNamespace>
        </plugin>
    </gazebo>
</robot>

