<?xml version="1.0"?>
<robot xmlns:xacro="http://www.ros.org/wiki/xacro" name="rover">

  <xacro:property name="base_width" value="0.7357" />
  <xacro:property name="base_len" value="1.0" />
  <xacro:property name="base_height" value="0.6" />
  <xacro:property name="wheel_radius" value="0.13" />
  <xacro:property name="wheel_width" value="0.1" />
  <xacro:property name="wheel_mass" value="2" />

  <!-- <xacro:property name="mesh_scale" value="0.0254 0.0254 0.0254" /> -->
  <xacro:property name="PI" value="3.141592" />

  <!--Interial macros-->
  <xacro:macro name="cylinder_inertia" params="m r h">
    <inertial>
      <mass value="${m}" />
      <inertia ixx="${m*(3*r*r+h*h)/12}" ixy="0" ixz="0" iyy="${m*(3*r*r+h*h)/12}" iyz="0" izz="${m*r*r/2}" />
    </inertial>
  </xacro:macro>

  <xacro:macro name="box_inertia" params="m w h d">
    <inertial>
      <mass value="${m}" />
      <inertia ixx="${m / 12.0 * (d*d + h*h)}" ixy="0.0" ixz="0.0" iyy="${m / 12.0 * (w*w + h*h)}" iyz="0.0" izz="${m / 12.0 * (w*w + d*d)}" />
    </inertial>
  </xacro:macro>

  <xacro:macro name="sphere_inertia" params="m r">
    <inertial>
      <mass value="${m}" />
      <inertia ixx="${2.0*m*(r*r)/5.0}" ixy="0.0" ixz="0.0" iyy="${2.0*m*(r*r)/5.0}" iyz="0.0" izz="${2.0*m*(r*r)/5.0}" />
    </inertial>
  </xacro:macro>


  <!--Base link-->
  <link name="base_link">
    <xacro:box_inertia m="3.0" w="${base_len}" h="${base_width}" d="${base_height}" />
    <visual>
      <origin rpy="0 0 0" xyz="-0.25 0.0 0.2" />
      <geometry>
        <mesh filename="package://mrover/rover_description/meshes/rover.dae" scale="1 1 1" />
      </geometry>
    </visual>
    <collision>
      <geometry>
        <box size="${base_len} ${base_width} ${base_height}" />
      </geometry>
    </collision>
  </link>

  <xacro:macro name="wheel" params="side reflect">
    <link name="front_${side}_wheel_link">
      <xacro:sphere_inertia m="${wheel_mass}" r="${wheel_radius}" />
      <visual>
        <origin rpy="${reflect * PI/2} 0 0" xyz="0.0 0.0 0.0" />
        <geometry>
          <mesh filename="package://mrover/rover_description/meshes/wheel.dae" scale="1 1 1" />
        </geometry>
      </visual>
      <collision>
        <geometry>
          <sphere radius="${wheel_radius}" />
        </geometry>
      </collision>
    </link>

    <link name="center_${side}_wheel_link">
      <xacro:cylinder_inertia m="${wheel_mass}" r="${wheel_radius}" h="${wheel_width}" />
      <visual>
        <origin rpy="${reflect * PI/2} 0 0" xyz="0.0 0.0 0.0" />
        <geometry>
          <mesh filename="package://mrover/rover_description/meshes/wheel.dae" scale="1 1 1" />
        </geometry>
      </visual>
      <collision>
        <geometry>
          <cylinder length="${wheel_width}" radius="${wheel_radius}" />
        </geometry>
      </collision>
    </link>

    <link name="back_${side}_wheel_link">
      <xacro:sphere_inertia m="${wheel_mass}" r="${wheel_radius}" />

      <visual>
        <origin rpy="${reflect * PI/2} 0 0" xyz="0.0 0.0 0.0" />
        <geometry>
          <mesh filename="package://mrover/rover_description/meshes/wheel.dae" scale="1 1 1" />
        </geometry>
      </visual>
      <collision>
        <geometry>
          <sphere radius="${wheel_radius}" />
        </geometry>
      </collision>
    </link>

    <joint name="front_${side}_wheel_joint" type="continuous">
      <parent link="base_link" />
      <child link="front_${side}_wheel_link" />
      <origin xyz="0.42 ${reflect * (base_width/2 + 0.06)} -0.27" rpy="${-PI/2} 0 0" />
      <axis xyz="0 0 1" />
    </joint>


    <joint name="center_${side}_wheel_joint" type="continuous">
      <parent link="base_link" />
      <child link="center_${side}_wheel_link" />
      <origin xyz="0 ${reflect * (base_width/2 + 0.06)} -0.27" rpy="${-PI/2} 0 0" />
      <axis xyz="0 0 1" />
    </joint>


    <joint name="back_${side}_wheel_joint" type="continuous">
      <parent link="base_link" />
      <child link="back_${side}_wheel_link" />
      <origin xyz="-0.42 ${reflect*(base_width/2 + 0.06)} -0.27" rpy="${-PI/2} 0 0" />
      <axis xyz="0 0 1" />
    </joint>
  </xacro:macro>

  <!-- IMU -->
  <joint name="imu_joint" type="fixed">
    <origin xyz="0 0 0.2" />
    <parent link="base_link" />
    <child link="imu_link" />
  </joint>

  <link name="imu_link"></link>

  <!-- Camera -->
  <joint name="camera_joint" type="fixed">
    <origin xyz="0 0 0.2" />
    <parent link="base_link" />
    <child link="camera_link" />
  </joint>

  <link name="camera_link">
    <collision>
      <origin xyz="0 0 0" rpy="0 0 0" />
      <geometry>
        <box size="0.01 0.1 0.01" />
      </geometry>
    </collision>

    <visual>
      <origin xyz="0 0 0" rpy="0 0 0" />
      <geometry>
        <mesh filename="package://mrover/rover_description/meshes/ZED2i.dae" scale="1 1 1" />
      </geometry>
    </visual>

    <inertial>
      <mass value="1e-5" />
      <origin xyz="0 0 0" rpy="0 0 0" />
      <inertia ixx="1e-6" ixy="0" ixz="0" iyy="1e-6" iyz="0" izz="1e-6" />
    </inertial>
  </link>

  <xacro:include filename="$(find mrover)/rover_description/rover_gazebo_plugins.xacro" />
  <xacro:wheel side="left" reflect="1" />
  <xacro:wheel side="right" reflect="-1" />
</robot>