<robot name="mrover_arm">
    <link name="chassis_link">
        <collision>
           <origin rpy="0.0 0 0" xyz="0 0 0"/>
           <geometry>
                <box size="0.8 0.6 0.4"/>
           </geometry> 
        </collision>
        <visual>
           <origin rpy="0.0 0 0" xyz="0 0 0"/>
           <geometry>
                <box size="0.8 0.6 0.4"/>
           </geometry> 
        </visual> 
        <inertial>
            <mass value="10"/>
            <inertia ixx="0.4" ixy="0.0" ixz="0.0" iyy="0.4" iyz="0.0" izz="0.2"/>
        </inertial>
    </link>
    <joint name="back_left_wheel_joint" type="continuous">    
        <origin rpy="1.570796 0 0" xyz="0.00 0.30 -0.1"/>    
        <child link="back_left_wheel_link" />    
        <parent link="chassis_link"/>    
        <axis rpy="0 0 0" xyz="0 0 1"/>    
        <limit effort="10000" velocity="1000"/>    
        <joint_properties damping="1.0" friction="1.0" />  
    </joint>
    <link name="back_left_wheel_link">
        <collision>
           <origin rpy="0.0 0 0" xyz="0 0 0"/>
           <geometry>
                <cylinder length="0.2" radius="0.2"/>
           </geometry> 
        </collision>
        <visual>
           <origin rpy="0.0 0 0" xyz="0 0 0"/>
           <geometry>
                <cylinder length="0.2" radius="0.2"/>
           </geometry> 
        </visual>
        <inertial>
            <mass value="10"/>
            <inertia ixx="0.4" ixy="0.0" ixz="0.0" iyy="0.4" iyz="0.0" izz="0.2"/>
        </inertial>
    </link>
    <joint name="back_right_wheel_joint" type="continuous">    
        <origin rpy="1.570796 0 0" xyz="0.00 -0.30 -0.1"/>    
        <child link="back_right_wheel_link" />    
        <parent link="chassis_link"/>    
        <axis rpy="0 0 0" xyz="0 0 1"/>    
        <limit effort="10000" velocity="1000"/>    
        <joint_properties damping="1.0" friction="1.0" />  
    </joint>
    <link name="back_right_wheel_link">
        <collision>
           <origin rpy="0.0 0 0" xyz="0 0 0"/>
           <geometry>
                <cylinder length="0.2" radius="0.2"/>
           </geometry> 
        </collision>
        <visual>
           <origin rpy="0.0 0 0" xyz="0 0 0"/>
           <geometry>
                <cylinder length="0.2" radius="0.2"/>
           </geometry> 
        </visual>
        <inertial>
            <mass value="10"/>
            <inertia ixx="0.4" ixy="0.0" ixz="0.0" iyy="0.4" iyz="0.0" izz="0.2"/>
        </inertial>
    </link>
</robot>